06/Oct/2022 23:50:18   ERROR    C:\Users\Asus\projects\skillfactory\NewsPortal1\venv\lib\site-packages\django\utils\log.py    Internal Server Error: /home/news/create  (<class 'TypeError'>, TypeError("Logger.error() missing 1 required positional argument: 'msg'"), <traceback object at 0x0000020734E18800>)
Traceback (most recent call last):
  File "C:\Users\Asus\projects\skillfactory\NewsPortal1\venv\lib\site-packages\redis\connection.py", line 611, in connect
    sock = self.retry.call_with_retry(
  File "C:\Users\Asus\projects\skillfactory\NewsPortal1\venv\lib\site-packages\redis\retry.py", line 46, in call_with_retry
    return do()
  File "C:\Users\Asus\projects\skillfactory\NewsPortal1\venv\lib\site-packages\redis\connection.py", line 612, in <lambda>
    lambda: self._connect(), lambda error: self.disconnect(error)
  File "C:\Users\Asus\projects\skillfactory\NewsPortal1\venv\lib\site-packages\redis\connection.py", line 645, in _connect
    for res in socket.getaddrinfo(
  File "C:\Program Files\WindowsApps\PythonSoftwareFoundation.Python.3.10_3.10.1776.0_x64__qbz5n2kfra8p0\lib\socket.py", line 955, in getaddrinfo
    for res in _socket.getaddrinfo(host, port, family, type, proto, flags):
socket.gaierror: [Errno 11001] getaddrinfo failed

During handling of the above exception, another exception occurred:

Traceback (most recent call last):
  File "C:\Users\Asus\projects\skillfactory\NewsPortal1\venv\lib\site-packages\celery\backends\redis.py", line 119, in reconnect_on_error
    yield
  File "C:\Users\Asus\projects\skillfactory\NewsPortal1\venv\lib\site-packages\celery\backends\redis.py", line 169, in _consume_from
    self._pubsub.subscribe(key)
  File "C:\Users\Asus\projects\skillfactory\NewsPortal1\venv\lib\site-packages\redis\client.py", line 1592, in subscribe
    ret_val = self.execute_command("SUBSCRIBE", *new_channels.keys())
  File "C:\Users\Asus\projects\skillfactory\NewsPortal1\venv\lib\site-packages\redis\client.py", line 1433, in execute_command
    self.connection = self.connection_pool.get_connection(
  File "C:\Users\Asus\projects\skillfactory\NewsPortal1\venv\lib\site-packages\redis\connection.py", line 1387, in get_connection
    connection.connect()
  File "C:\Users\Asus\projects\skillfactory\NewsPortal1\venv\lib\site-packages\redis\connection.py", line 617, in connect
    raise ConnectionError(self._error_message(e))
redis.exceptions.ConnectionError: Error 11001 connecting to redis-15204.c81.us-east-1-2.ec2.cloud.redislabs.com:15204. getaddrinfo failed.

During handling of the above exception, another exception occurred:

Traceback (most recent call last):
  File "C:\Users\Asus\projects\skillfactory\NewsPortal1\venv\lib\site-packages\redis\connection.py", line 611, in connect
    sock = self.retry.call_with_retry(
  File "C:\Users\Asus\projects\skillfactory\NewsPortal1\venv\lib\site-packages\redis\retry.py", line 46, in call_with_retry
    return do()
  File "C:\Users\Asus\projects\skillfactory\NewsPortal1\venv\lib\site-packages\redis\connection.py", line 612, in <lambda>
    lambda: self._connect(), lambda error: self.disconnect(error)
  File "C:\Users\Asus\projects\skillfactory\NewsPortal1\venv\lib\site-packages\redis\connection.py", line 645, in _connect
    for res in socket.getaddrinfo(
  File "C:\Program Files\WindowsApps\PythonSoftwareFoundation.Python.3.10_3.10.1776.0_x64__qbz5n2kfra8p0\lib\socket.py", line 955, in getaddrinfo
    for res in _socket.getaddrinfo(host, port, family, type, proto, flags):
socket.gaierror: [Errno 11001] getaddrinfo failed

During handling of the above exception, another exception occurred:

Traceback (most recent call last):
  File "C:\Users\Asus\projects\skillfactory\NewsPortal1\venv\lib\site-packages\kombu\connection.py", line 446, in _reraise_as_library_errors
    yield
  File "C:\Users\Asus\projects\skillfactory\NewsPortal1\venv\lib\site-packages\celery\app\base.py", line 787, in send_task
    self.backend.on_task_call(P, task_id)
  File "C:\Users\Asus\projects\skillfactory\NewsPortal1\venv\lib\site-packages\celery\backends\redis.py", line 365, in on_task_call
    self.result_consumer.consume_from(task_id)
  File "C:\Users\Asus\projects\skillfactory\NewsPortal1\venv\lib\site-packages\celery\backends\redis.py", line 161, in consume_from
    return self.start(task_id)
  File "C:\Users\Asus\projects\skillfactory\NewsPortal1\venv\lib\site-packages\celery\backends\redis.py", line 139, in start
    self._consume_from(initial_task_id)
  File "C:\Users\Asus\projects\skillfactory\NewsPortal1\venv\lib\site-packages\celery\backends\redis.py", line 168, in _consume_from
    with self.reconnect_on_error():
  File "C:\Program Files\WindowsApps\PythonSoftwareFoundation.Python.3.10_3.10.1776.0_x64__qbz5n2kfra8p0\lib\contextlib.py", line 153, in __exit__
    self.gen.throw(typ, value, traceback)
  File "C:\Users\Asus\projects\skillfactory\NewsPortal1\venv\lib\site-packages\celery\backends\redis.py", line 122, in reconnect_on_error
    self._ensure(self._reconnect_pubsub, ())
  File "C:\Users\Asus\projects\skillfactory\NewsPortal1\venv\lib\site-packages\celery\backends\redis.py", line 376, in ensure
    return retry_over_time(
  File "C:\Users\Asus\projects\skillfactory\NewsPortal1\venv\lib\site-packages\kombu\utils\functional.py", line 312, in retry_over_time
    return fun(*args, **kwargs)
  File "C:\Users\Asus\projects\skillfactory\NewsPortal1\venv\lib\site-packages\celery\backends\redis.py", line 106, in _reconnect_pubsub
    metas = self.backend.client.mget(self.subscribed_to)
  File "C:\Users\Asus\projects\skillfactory\NewsPortal1\venv\lib\site-packages\redis\commands\core.py", line 1893, in mget
    return self.execute_command("MGET", *args, **options)
  File "C:\Users\Asus\projects\skillfactory\NewsPortal1\venv\lib\site-packages\redis\client.py", line 1235, in execute_command
    conn = self.connection or pool.get_connection(command_name, **options)
  File "C:\Users\Asus\projects\skillfactory\NewsPortal1\venv\lib\site-packages\redis\connection.py", line 1387, in get_connection
    connection.connect()
  File "C:\Users\Asus\projects\skillfactory\NewsPortal1\venv\lib\site-packages\redis\connection.py", line 617, in connect
    raise ConnectionError(self._error_message(e))
redis.exceptions.ConnectionError: Error 11001 connecting to redis-15204.c81.us-east-1-2.ec2.cloud.redislabs.com:15204. getaddrinfo failed.

The above exception was the direct cause of the following exception:

Traceback (most recent call last):
  File "C:\Users\Asus\projects\skillfactory\NewsPortal1\newsWeb\news\views.py", line 117, in form_valid
    send_mail_news.delay ( Create_news.id, id_categories )  # вызов функции отправки почты из tasks.py
  File "C:\Users\Asus\projects\skillfactory\NewsPortal1\venv\lib\site-packages\celery\app\task.py", line 425, in delay
    return self.apply_async(args, kwargs)
  File "C:\Users\Asus\projects\skillfactory\NewsPortal1\venv\lib\site-packages\celery\app\task.py", line 575, in apply_async
    return app.send_task(
  File "C:\Users\Asus\projects\skillfactory\NewsPortal1\venv\lib\site-packages\celery\app\base.py", line 785, in send_task
    with P.connection._reraise_as_library_errors():
  File "C:\Program Files\WindowsApps\PythonSoftwareFoundation.Python.3.10_3.10.1776.0_x64__qbz5n2kfra8p0\lib\contextlib.py", line 153, in __exit__
    self.gen.throw(typ, value, traceback)
  File "C:\Users\Asus\projects\skillfactory\NewsPortal1\venv\lib\site-packages\kombu\connection.py", line 450, in _reraise_as_library_errors
    raise ConnectionError(str(exc)) from exc
kombu.exceptions.OperationalError: Error 11001 connecting to redis-15204.c81.us-east-1-2.ec2.cloud.redislabs.com:15204. getaddrinfo failed.

During handling of the above exception, another exception occurred:

Traceback (most recent call last):
  File "C:\Users\Asus\projects\skillfactory\NewsPortal1\venv\lib\site-packages\django\core\handlers\exception.py", line 55, in inner
    response = get_response(request)
  File "C:\Users\Asus\projects\skillfactory\NewsPortal1\venv\lib\site-packages\django\core\handlers\base.py", line 197, in _get_response
    response = wrapped_callback(request, *callback_args, **callback_kwargs)
  File "C:\Users\Asus\projects\skillfactory\NewsPortal1\venv\lib\site-packages\django\views\generic\base.py", line 84, in view
    return self.dispatch(request, *args, **kwargs)
  File "C:\Users\Asus\projects\skillfactory\NewsPortal1\venv\lib\site-packages\django\contrib\auth\mixins.py", line 109, in dispatch
    return super().dispatch(request, *args, **kwargs)
  File "C:\Users\Asus\projects\skillfactory\NewsPortal1\venv\lib\site-packages\django\views\generic\base.py", line 119, in dispatch
    return handler(request, *args, **kwargs)
  File "C:\Users\Asus\projects\skillfactory\NewsPortal1\venv\lib\site-packages\django\views\generic\edit.py", line 184, in post
    return super().post(request, *args, **kwargs)
  File "C:\Users\Asus\projects\skillfactory\NewsPortal1\venv\lib\site-packages\django\views\generic\edit.py", line 153, in post
    return self.form_valid(form)
  File "C:\Users\Asus\projects\skillfactory\NewsPortal1\newsWeb\news\views.py", line 120, in form_valid
    logging.Logger.error("error - can`t sent email")
TypeError: Logger.error() missing 1 required positional argument: 'msg'
06/Oct/2022 23:50:18   ERROR    C:\Users\Asus\projects\skillfactory\NewsPortal1\venv\lib\site-packages\django\core\servers\basehttp.py    "POST /home/news/create HTTP/1.1" 500 283707  None
07/Oct/2022 00:00:12   ERROR    C:\Users\Asus\projects\skillfactory\NewsPortal1\venv\lib\site-packages\django\utils\log.py    Internal Server Error: /home/news/create  (<class 'TypeError'>, TypeError("Logger.error() missing 1 required positional argument: 'msg'"), <traceback object at 0x000001E6CA7F1FC0>)
Traceback (most recent call last):
  File "C:\Users\Asus\projects\skillfactory\NewsPortal1\newsWeb\news\signals.py", line 20, in notify_managers_news
    mail_managers (
  File "C:\Users\Asus\projects\skillfactory\NewsPortal1\venv\lib\site-packages\django\core\mail\__init__.py", line 154, in mail_managers
    mail.send(fail_silently=fail_silently)
  File "C:\Users\Asus\projects\skillfactory\NewsPortal1\venv\lib\site-packages\django\core\mail\message.py", line 298, in send
    return self.get_connection(fail_silently).send_messages([self])
  File "C:\Users\Asus\projects\skillfactory\NewsPortal1\venv\lib\site-packages\django\core\mail\backends\smtp.py", line 124, in send_messages
    new_conn_created = self.open()
  File "C:\Users\Asus\projects\skillfactory\NewsPortal1\venv\lib\site-packages\django\core\mail\backends\smtp.py", line 80, in open
    self.connection = self.connection_class(
  File "C:\Program Files\WindowsApps\PythonSoftwareFoundation.Python.3.10_3.10.1776.0_x64__qbz5n2kfra8p0\lib\smtplib.py", line 1050, in __init__
    SMTP.__init__(self, host, port, local_hostname, timeout,
  File "C:\Program Files\WindowsApps\PythonSoftwareFoundation.Python.3.10_3.10.1776.0_x64__qbz5n2kfra8p0\lib\smtplib.py", line 255, in __init__
    (code, msg) = self.connect(host, port)
  File "C:\Program Files\WindowsApps\PythonSoftwareFoundation.Python.3.10_3.10.1776.0_x64__qbz5n2kfra8p0\lib\smtplib.py", line 341, in connect
    self.sock = self._get_socket(host, port, self.timeout)
  File "C:\Program Files\WindowsApps\PythonSoftwareFoundation.Python.3.10_3.10.1776.0_x64__qbz5n2kfra8p0\lib\smtplib.py", line 1056, in _get_socket
    new_socket = super()._get_socket(host, port, timeout)
  File "C:\Program Files\WindowsApps\PythonSoftwareFoundation.Python.3.10_3.10.1776.0_x64__qbz5n2kfra8p0\lib\smtplib.py", line 312, in _get_socket
    return socket.create_connection((host, port), timeout,
  File "C:\Program Files\WindowsApps\PythonSoftwareFoundation.Python.3.10_3.10.1776.0_x64__qbz5n2kfra8p0\lib\socket.py", line 824, in create_connection
    for res in getaddrinfo(host, port, 0, SOCK_STREAM):
  File "C:\Program Files\WindowsApps\PythonSoftwareFoundation.Python.3.10_3.10.1776.0_x64__qbz5n2kfra8p0\lib\socket.py", line 955, in getaddrinfo
    for res in _socket.getaddrinfo(host, port, family, type, proto, flags):
socket.gaierror: [Errno 11001] getaddrinfo failed

During handling of the above exception, another exception occurred:

Traceback (most recent call last):
  File "C:\Users\Asus\projects\skillfactory\NewsPortal1\venv\lib\site-packages\django\core\handlers\exception.py", line 55, in inner
    response = get_response(request)
  File "C:\Users\Asus\projects\skillfactory\NewsPortal1\venv\lib\site-packages\django\core\handlers\base.py", line 197, in _get_response
    response = wrapped_callback(request, *callback_args, **callback_kwargs)
  File "C:\Users\Asus\projects\skillfactory\NewsPortal1\venv\lib\site-packages\django\views\generic\base.py", line 84, in view
    return self.dispatch(request, *args, **kwargs)
  File "C:\Users\Asus\projects\skillfactory\NewsPortal1\venv\lib\site-packages\django\contrib\auth\mixins.py", line 109, in dispatch
    return super().dispatch(request, *args, **kwargs)
  File "C:\Users\Asus\projects\skillfactory\NewsPortal1\venv\lib\site-packages\django\views\generic\base.py", line 119, in dispatch
    return handler(request, *args, **kwargs)
  File "C:\Users\Asus\projects\skillfactory\NewsPortal1\venv\lib\site-packages\django\views\generic\edit.py", line 184, in post
    return super().post(request, *args, **kwargs)
  File "C:\Users\Asus\projects\skillfactory\NewsPortal1\venv\lib\site-packages\django\views\generic\edit.py", line 153, in post
    return self.form_valid(form)
  File "C:\Users\Asus\projects\skillfactory\NewsPortal1\newsWeb\news\views.py", line 108, in form_valid
    Create_news.save()
  File "C:\Users\Asus\projects\skillfactory\NewsPortal1\venv\lib\site-packages\django\db\models\base.py", line 806, in save
    self.save_base(
  File "C:\Users\Asus\projects\skillfactory\NewsPortal1\venv\lib\site-packages\django\db\models\base.py", line 872, in save_base
    post_save.send(
  File "C:\Users\Asus\projects\skillfactory\NewsPortal1\venv\lib\site-packages\django\dispatch\dispatcher.py", line 176, in send
    return [
  File "C:\Users\Asus\projects\skillfactory\NewsPortal1\venv\lib\site-packages\django\dispatch\dispatcher.py", line 177, in <listcomp>
    (receiver, receiver(signal=self, sender=sender, **named))
  File "C:\Users\Asus\projects\skillfactory\NewsPortal1\newsWeb\news\signals.py", line 27, in notify_managers_news
    logging.Logger.error ( "error - can`t sent email" )
TypeError: Logger.error() missing 1 required positional argument: 'msg'
07/Oct/2022 00:00:12   ERROR    C:\Users\Asus\projects\skillfactory\NewsPortal1\venv\lib\site-packages\django\core\servers\basehttp.py    "POST /home/news/create HTTP/1.1" 500 172597  None
07/Oct/2022 00:02:05   ERROR    C:\Users\Asus\projects\skillfactory\NewsPortal1\venv\lib\site-packages\django\utils\log.py    Internal Server Error: /home/news/create  (<class 'AttributeError'>, AttributeError("'str' object has no attribute 'isEnabledFor'"), <traceback object at 0x00000157ED387040>)
Traceback (most recent call last):
  File "C:\Users\Asus\projects\skillfactory\NewsPortal1\newsWeb\news\signals.py", line 20, in notify_managers_news
    mail_managers (
  File "C:\Users\Asus\projects\skillfactory\NewsPortal1\venv\lib\site-packages\django\core\mail\__init__.py", line 154, in mail_managers
    mail.send(fail_silently=fail_silently)
  File "C:\Users\Asus\projects\skillfactory\NewsPortal1\venv\lib\site-packages\django\core\mail\message.py", line 298, in send
    return self.get_connection(fail_silently).send_messages([self])
  File "C:\Users\Asus\projects\skillfactory\NewsPortal1\venv\lib\site-packages\django\core\mail\backends\smtp.py", line 124, in send_messages
    new_conn_created = self.open()
  File "C:\Users\Asus\projects\skillfactory\NewsPortal1\venv\lib\site-packages\django\core\mail\backends\smtp.py", line 80, in open
    self.connection = self.connection_class(
  File "C:\Program Files\WindowsApps\PythonSoftwareFoundation.Python.3.10_3.10.1776.0_x64__qbz5n2kfra8p0\lib\smtplib.py", line 1050, in __init__
    SMTP.__init__(self, host, port, local_hostname, timeout,
  File "C:\Program Files\WindowsApps\PythonSoftwareFoundation.Python.3.10_3.10.1776.0_x64__qbz5n2kfra8p0\lib\smtplib.py", line 255, in __init__
    (code, msg) = self.connect(host, port)
  File "C:\Program Files\WindowsApps\PythonSoftwareFoundation.Python.3.10_3.10.1776.0_x64__qbz5n2kfra8p0\lib\smtplib.py", line 341, in connect
    self.sock = self._get_socket(host, port, self.timeout)
  File "C:\Program Files\WindowsApps\PythonSoftwareFoundation.Python.3.10_3.10.1776.0_x64__qbz5n2kfra8p0\lib\smtplib.py", line 1056, in _get_socket
    new_socket = super()._get_socket(host, port, timeout)
  File "C:\Program Files\WindowsApps\PythonSoftwareFoundation.Python.3.10_3.10.1776.0_x64__qbz5n2kfra8p0\lib\smtplib.py", line 312, in _get_socket
    return socket.create_connection((host, port), timeout,
  File "C:\Program Files\WindowsApps\PythonSoftwareFoundation.Python.3.10_3.10.1776.0_x64__qbz5n2kfra8p0\lib\socket.py", line 824, in create_connection
    for res in getaddrinfo(host, port, 0, SOCK_STREAM):
  File "C:\Program Files\WindowsApps\PythonSoftwareFoundation.Python.3.10_3.10.1776.0_x64__qbz5n2kfra8p0\lib\socket.py", line 955, in getaddrinfo
    for res in _socket.getaddrinfo(host, port, family, type, proto, flags):
socket.gaierror: [Errno 11001] getaddrinfo failed

During handling of the above exception, another exception occurred:

Traceback (most recent call last):
  File "C:\Users\Asus\projects\skillfactory\NewsPortal1\venv\lib\site-packages\django\core\handlers\exception.py", line 55, in inner
    response = get_response(request)
  File "C:\Users\Asus\projects\skillfactory\NewsPortal1\venv\lib\site-packages\django\core\handlers\base.py", line 197, in _get_response
    response = wrapped_callback(request, *callback_args, **callback_kwargs)
  File "C:\Users\Asus\projects\skillfactory\NewsPortal1\venv\lib\site-packages\django\views\generic\base.py", line 84, in view
    return self.dispatch(request, *args, **kwargs)
  File "C:\Users\Asus\projects\skillfactory\NewsPortal1\venv\lib\site-packages\django\contrib\auth\mixins.py", line 109, in dispatch
    return super().dispatch(request, *args, **kwargs)
  File "C:\Users\Asus\projects\skillfactory\NewsPortal1\venv\lib\site-packages\django\views\generic\base.py", line 119, in dispatch
    return handler(request, *args, **kwargs)
  File "C:\Users\Asus\projects\skillfactory\NewsPortal1\venv\lib\site-packages\django\views\generic\edit.py", line 184, in post
    return super().post(request, *args, **kwargs)
  File "C:\Users\Asus\projects\skillfactory\NewsPortal1\venv\lib\site-packages\django\views\generic\edit.py", line 153, in post
    return self.form_valid(form)
  File "C:\Users\Asus\projects\skillfactory\NewsPortal1\newsWeb\news\views.py", line 108, in form_valid
    Create_news.save()
  File "C:\Users\Asus\projects\skillfactory\NewsPortal1\venv\lib\site-packages\django\db\models\base.py", line 806, in save
    self.save_base(
  File "C:\Users\Asus\projects\skillfactory\NewsPortal1\venv\lib\site-packages\django\db\models\base.py", line 872, in save_base
    post_save.send(
  File "C:\Users\Asus\projects\skillfactory\NewsPortal1\venv\lib\site-packages\django\dispatch\dispatcher.py", line 176, in send
    return [
  File "C:\Users\Asus\projects\skillfactory\NewsPortal1\venv\lib\site-packages\django\dispatch\dispatcher.py", line 177, in <listcomp>
    (receiver, receiver(signal=self, sender=sender, **named))
  File "C:\Users\Asus\projects\skillfactory\NewsPortal1\newsWeb\news\signals.py", line 27, in notify_managers_news
    logging.Logger.error ('dvefdvs', "error - can`t sent email" )
  File "C:\Program Files\WindowsApps\PythonSoftwareFoundation.Python.3.10_3.10.1776.0_x64__qbz5n2kfra8p0\lib\logging\__init__.py", line 1505, in error
    if self.isEnabledFor(ERROR):
AttributeError: 'str' object has no attribute 'isEnabledFor'
07/Oct/2022 00:02:05   ERROR    C:\Users\Asus\projects\skillfactory\NewsPortal1\venv\lib\site-packages\django\core\servers\basehttp.py    "POST /home/news/create HTTP/1.1" 500 176878  None
07/Oct/2022 00:02:52   ERROR    C:\Users\Asus\projects\skillfactory\NewsPortal1\venv\lib\site-packages\django\utils\log.py    Internal Server Error: /home/news/create  (<class 'AttributeError'>, AttributeError("'str' object has no attribute 'isEnabledFor'"), <traceback object at 0x00000157ED667000>)
Traceback (most recent call last):
  File "C:\Users\Asus\projects\skillfactory\NewsPortal1\newsWeb\news\signals.py", line 20, in notify_managers_news
    mail_managers (
  File "C:\Users\Asus\projects\skillfactory\NewsPortal1\venv\lib\site-packages\django\core\mail\__init__.py", line 154, in mail_managers
    mail.send(fail_silently=fail_silently)
  File "C:\Users\Asus\projects\skillfactory\NewsPortal1\venv\lib\site-packages\django\core\mail\message.py", line 298, in send
    return self.get_connection(fail_silently).send_messages([self])
  File "C:\Users\Asus\projects\skillfactory\NewsPortal1\venv\lib\site-packages\django\core\mail\backends\smtp.py", line 124, in send_messages
    new_conn_created = self.open()
  File "C:\Users\Asus\projects\skillfactory\NewsPortal1\venv\lib\site-packages\django\core\mail\backends\smtp.py", line 80, in open
    self.connection = self.connection_class(
  File "C:\Program Files\WindowsApps\PythonSoftwareFoundation.Python.3.10_3.10.1776.0_x64__qbz5n2kfra8p0\lib\smtplib.py", line 1050, in __init__
    SMTP.__init__(self, host, port, local_hostname, timeout,
  File "C:\Program Files\WindowsApps\PythonSoftwareFoundation.Python.3.10_3.10.1776.0_x64__qbz5n2kfra8p0\lib\smtplib.py", line 255, in __init__
    (code, msg) = self.connect(host, port)
  File "C:\Program Files\WindowsApps\PythonSoftwareFoundation.Python.3.10_3.10.1776.0_x64__qbz5n2kfra8p0\lib\smtplib.py", line 341, in connect
    self.sock = self._get_socket(host, port, self.timeout)
  File "C:\Program Files\WindowsApps\PythonSoftwareFoundation.Python.3.10_3.10.1776.0_x64__qbz5n2kfra8p0\lib\smtplib.py", line 1056, in _get_socket
    new_socket = super()._get_socket(host, port, timeout)
  File "C:\Program Files\WindowsApps\PythonSoftwareFoundation.Python.3.10_3.10.1776.0_x64__qbz5n2kfra8p0\lib\smtplib.py", line 312, in _get_socket
    return socket.create_connection((host, port), timeout,
  File "C:\Program Files\WindowsApps\PythonSoftwareFoundation.Python.3.10_3.10.1776.0_x64__qbz5n2kfra8p0\lib\socket.py", line 824, in create_connection
    for res in getaddrinfo(host, port, 0, SOCK_STREAM):
  File "C:\Program Files\WindowsApps\PythonSoftwareFoundation.Python.3.10_3.10.1776.0_x64__qbz5n2kfra8p0\lib\socket.py", line 955, in getaddrinfo
    for res in _socket.getaddrinfo(host, port, family, type, proto, flags):
socket.gaierror: [Errno 11001] getaddrinfo failed

During handling of the above exception, another exception occurred:

Traceback (most recent call last):
  File "C:\Users\Asus\projects\skillfactory\NewsPortal1\venv\lib\site-packages\django\core\handlers\exception.py", line 55, in inner
    response = get_response(request)
  File "C:\Users\Asus\projects\skillfactory\NewsPortal1\venv\lib\site-packages\django\core\handlers\base.py", line 197, in _get_response
    response = wrapped_callback(request, *callback_args, **callback_kwargs)
  File "C:\Users\Asus\projects\skillfactory\NewsPortal1\venv\lib\site-packages\django\views\generic\base.py", line 84, in view
    return self.dispatch(request, *args, **kwargs)
  File "C:\Users\Asus\projects\skillfactory\NewsPortal1\venv\lib\site-packages\django\contrib\auth\mixins.py", line 109, in dispatch
    return super().dispatch(request, *args, **kwargs)
  File "C:\Users\Asus\projects\skillfactory\NewsPortal1\venv\lib\site-packages\django\views\generic\base.py", line 119, in dispatch
    return handler(request, *args, **kwargs)
  File "C:\Users\Asus\projects\skillfactory\NewsPortal1\venv\lib\site-packages\django\views\generic\edit.py", line 184, in post
    return super().post(request, *args, **kwargs)
  File "C:\Users\Asus\projects\skillfactory\NewsPortal1\venv\lib\site-packages\django\views\generic\edit.py", line 153, in post
    return self.form_valid(form)
  File "C:\Users\Asus\projects\skillfactory\NewsPortal1\newsWeb\news\views.py", line 108, in form_valid
    Create_news.save()
  File "C:\Users\Asus\projects\skillfactory\NewsPortal1\venv\lib\site-packages\django\db\models\base.py", line 806, in save
    self.save_base(
  File "C:\Users\Asus\projects\skillfactory\NewsPortal1\venv\lib\site-packages\django\db\models\base.py", line 872, in save_base
    post_save.send(
  File "C:\Users\Asus\projects\skillfactory\NewsPortal1\venv\lib\site-packages\django\dispatch\dispatcher.py", line 176, in send
    return [
  File "C:\Users\Asus\projects\skillfactory\NewsPortal1\venv\lib\site-packages\django\dispatch\dispatcher.py", line 177, in <listcomp>
    (receiver, receiver(signal=self, sender=sender, **named))
  File "C:\Users\Asus\projects\skillfactory\NewsPortal1\newsWeb\news\signals.py", line 27, in notify_managers_news
    logging.Logger.error ('dvefdvs', "error - can`t sent email" )
  File "C:\Program Files\WindowsApps\PythonSoftwareFoundation.Python.3.10_3.10.1776.0_x64__qbz5n2kfra8p0\lib\logging\__init__.py", line 1505, in error
    if self.isEnabledFor(ERROR):
AttributeError: 'str' object has no attribute 'isEnabledFor'
07/Oct/2022 00:02:52   ERROR    C:\Users\Asus\projects\skillfactory\NewsPortal1\venv\lib\site-packages\django\core\servers\basehttp.py    "POST /home/news/create HTTP/1.1" 500 176878  None
07/Oct/2022 00:04:03   ERROR    C:\Users\Asus\projects\skillfactory\NewsPortal1\venv\lib\site-packages\django\utils\log.py    Internal Server Error: /home/news/create  (<class 'AttributeError'>, AttributeError("'str' object has no attribute 'isEnabledFor'"), <traceback object at 0x000001A955B7C1C0>)
Traceback (most recent call last):
  File "C:\Users\Asus\projects\skillfactory\NewsPortal1\newsWeb\news\signals.py", line 20, in notify_managers_news
    mail_managers (
  File "C:\Users\Asus\projects\skillfactory\NewsPortal1\venv\lib\site-packages\django\core\mail\__init__.py", line 154, in mail_managers
    mail.send(fail_silently=fail_silently)
  File "C:\Users\Asus\projects\skillfactory\NewsPortal1\venv\lib\site-packages\django\core\mail\message.py", line 298, in send
    return self.get_connection(fail_silently).send_messages([self])
  File "C:\Users\Asus\projects\skillfactory\NewsPortal1\venv\lib\site-packages\django\core\mail\backends\smtp.py", line 124, in send_messages
    new_conn_created = self.open()
  File "C:\Users\Asus\projects\skillfactory\NewsPortal1\venv\lib\site-packages\django\core\mail\backends\smtp.py", line 80, in open
    self.connection = self.connection_class(
  File "C:\Program Files\WindowsApps\PythonSoftwareFoundation.Python.3.10_3.10.1776.0_x64__qbz5n2kfra8p0\lib\smtplib.py", line 1050, in __init__
    SMTP.__init__(self, host, port, local_hostname, timeout,
  File "C:\Program Files\WindowsApps\PythonSoftwareFoundation.Python.3.10_3.10.1776.0_x64__qbz5n2kfra8p0\lib\smtplib.py", line 255, in __init__
    (code, msg) = self.connect(host, port)
  File "C:\Program Files\WindowsApps\PythonSoftwareFoundation.Python.3.10_3.10.1776.0_x64__qbz5n2kfra8p0\lib\smtplib.py", line 341, in connect
    self.sock = self._get_socket(host, port, self.timeout)
  File "C:\Program Files\WindowsApps\PythonSoftwareFoundation.Python.3.10_3.10.1776.0_x64__qbz5n2kfra8p0\lib\smtplib.py", line 1056, in _get_socket
    new_socket = super()._get_socket(host, port, timeout)
  File "C:\Program Files\WindowsApps\PythonSoftwareFoundation.Python.3.10_3.10.1776.0_x64__qbz5n2kfra8p0\lib\smtplib.py", line 312, in _get_socket
    return socket.create_connection((host, port), timeout,
  File "C:\Program Files\WindowsApps\PythonSoftwareFoundation.Python.3.10_3.10.1776.0_x64__qbz5n2kfra8p0\lib\socket.py", line 824, in create_connection
    for res in getaddrinfo(host, port, 0, SOCK_STREAM):
  File "C:\Program Files\WindowsApps\PythonSoftwareFoundation.Python.3.10_3.10.1776.0_x64__qbz5n2kfra8p0\lib\socket.py", line 955, in getaddrinfo
    for res in _socket.getaddrinfo(host, port, family, type, proto, flags):
socket.gaierror: [Errno 11001] getaddrinfo failed

During handling of the above exception, another exception occurred:

Traceback (most recent call last):
  File "C:\Users\Asus\projects\skillfactory\NewsPortal1\venv\lib\site-packages\django\core\handlers\exception.py", line 55, in inner
    response = get_response(request)
  File "C:\Users\Asus\projects\skillfactory\NewsPortal1\venv\lib\site-packages\django\core\handlers\base.py", line 197, in _get_response
    response = wrapped_callback(request, *callback_args, **callback_kwargs)
  File "C:\Users\Asus\projects\skillfactory\NewsPortal1\venv\lib\site-packages\django\views\generic\base.py", line 84, in view
    return self.dispatch(request, *args, **kwargs)
  File "C:\Users\Asus\projects\skillfactory\NewsPortal1\venv\lib\site-packages\django\contrib\auth\mixins.py", line 109, in dispatch
    return super().dispatch(request, *args, **kwargs)
  File "C:\Users\Asus\projects\skillfactory\NewsPortal1\venv\lib\site-packages\django\views\generic\base.py", line 119, in dispatch
    return handler(request, *args, **kwargs)
  File "C:\Users\Asus\projects\skillfactory\NewsPortal1\venv\lib\site-packages\django\views\generic\edit.py", line 184, in post
    return super().post(request, *args, **kwargs)
  File "C:\Users\Asus\projects\skillfactory\NewsPortal1\venv\lib\site-packages\django\views\generic\edit.py", line 153, in post
    return self.form_valid(form)
  File "C:\Users\Asus\projects\skillfactory\NewsPortal1\newsWeb\news\views.py", line 108, in form_valid
    Create_news.save()
  File "C:\Users\Asus\projects\skillfactory\NewsPortal1\venv\lib\site-packages\django\db\models\base.py", line 806, in save
    self.save_base(
  File "C:\Users\Asus\projects\skillfactory\NewsPortal1\venv\lib\site-packages\django\db\models\base.py", line 872, in save_base
    post_save.send(
  File "C:\Users\Asus\projects\skillfactory\NewsPortal1\venv\lib\site-packages\django\dispatch\dispatcher.py", line 176, in send
    return [
  File "C:\Users\Asus\projects\skillfactory\NewsPortal1\venv\lib\site-packages\django\dispatch\dispatcher.py", line 177, in <listcomp>
    (receiver, receiver(signal=self, sender=sender, **named))
  File "C:\Users\Asus\projects\skillfactory\NewsPortal1\newsWeb\news\signals.py", line 27, in notify_managers_news
    logging.Logger.error ('dvefdvs', 'error - can`t sent email', exc_info=1 )
  File "C:\Program Files\WindowsApps\PythonSoftwareFoundation.Python.3.10_3.10.1776.0_x64__qbz5n2kfra8p0\lib\logging\__init__.py", line 1505, in error
    if self.isEnabledFor(ERROR):
AttributeError: 'str' object has no attribute 'isEnabledFor'
07/Oct/2022 00:04:03   ERROR    C:\Users\Asus\projects\skillfactory\NewsPortal1\venv\lib\site-packages\django\core\servers\basehttp.py    "POST /home/news/create HTTP/1.1" 500 176925  None
07/Oct/2022 00:04:26   ERROR    C:\Users\Asus\projects\skillfactory\NewsPortal1\venv\lib\site-packages\django\utils\log.py    Internal Server Error: /home/news/create  (<class 'TypeError'>, TypeError("Logger.error() missing 1 required positional argument: 'msg'"), <traceback object at 0x000002808F98FAC0>)
Traceback (most recent call last):
  File "C:\Users\Asus\projects\skillfactory\NewsPortal1\newsWeb\news\signals.py", line 20, in notify_managers_news
    mail_managers (
  File "C:\Users\Asus\projects\skillfactory\NewsPortal1\venv\lib\site-packages\django\core\mail\__init__.py", line 154, in mail_managers
    mail.send(fail_silently=fail_silently)
  File "C:\Users\Asus\projects\skillfactory\NewsPortal1\venv\lib\site-packages\django\core\mail\message.py", line 298, in send
    return self.get_connection(fail_silently).send_messages([self])
  File "C:\Users\Asus\projects\skillfactory\NewsPortal1\venv\lib\site-packages\django\core\mail\backends\smtp.py", line 124, in send_messages
    new_conn_created = self.open()
  File "C:\Users\Asus\projects\skillfactory\NewsPortal1\venv\lib\site-packages\django\core\mail\backends\smtp.py", line 80, in open
    self.connection = self.connection_class(
  File "C:\Program Files\WindowsApps\PythonSoftwareFoundation.Python.3.10_3.10.1776.0_x64__qbz5n2kfra8p0\lib\smtplib.py", line 1050, in __init__
    SMTP.__init__(self, host, port, local_hostname, timeout,
  File "C:\Program Files\WindowsApps\PythonSoftwareFoundation.Python.3.10_3.10.1776.0_x64__qbz5n2kfra8p0\lib\smtplib.py", line 255, in __init__
    (code, msg) = self.connect(host, port)
  File "C:\Program Files\WindowsApps\PythonSoftwareFoundation.Python.3.10_3.10.1776.0_x64__qbz5n2kfra8p0\lib\smtplib.py", line 341, in connect
    self.sock = self._get_socket(host, port, self.timeout)
  File "C:\Program Files\WindowsApps\PythonSoftwareFoundation.Python.3.10_3.10.1776.0_x64__qbz5n2kfra8p0\lib\smtplib.py", line 1056, in _get_socket
    new_socket = super()._get_socket(host, port, timeout)
  File "C:\Program Files\WindowsApps\PythonSoftwareFoundation.Python.3.10_3.10.1776.0_x64__qbz5n2kfra8p0\lib\smtplib.py", line 312, in _get_socket
    return socket.create_connection((host, port), timeout,
  File "C:\Program Files\WindowsApps\PythonSoftwareFoundation.Python.3.10_3.10.1776.0_x64__qbz5n2kfra8p0\lib\socket.py", line 824, in create_connection
    for res in getaddrinfo(host, port, 0, SOCK_STREAM):
  File "C:\Program Files\WindowsApps\PythonSoftwareFoundation.Python.3.10_3.10.1776.0_x64__qbz5n2kfra8p0\lib\socket.py", line 955, in getaddrinfo
    for res in _socket.getaddrinfo(host, port, family, type, proto, flags):
socket.gaierror: [Errno 11001] getaddrinfo failed

During handling of the above exception, another exception occurred:

Traceback (most recent call last):
  File "C:\Users\Asus\projects\skillfactory\NewsPortal1\venv\lib\site-packages\django\core\handlers\exception.py", line 55, in inner
    response = get_response(request)
  File "C:\Users\Asus\projects\skillfactory\NewsPortal1\venv\lib\site-packages\django\core\handlers\base.py", line 197, in _get_response
    response = wrapped_callback(request, *callback_args, **callback_kwargs)
  File "C:\Users\Asus\projects\skillfactory\NewsPortal1\venv\lib\site-packages\django\views\generic\base.py", line 84, in view
    return self.dispatch(request, *args, **kwargs)
  File "C:\Users\Asus\projects\skillfactory\NewsPortal1\venv\lib\site-packages\django\contrib\auth\mixins.py", line 109, in dispatch
    return super().dispatch(request, *args, **kwargs)
  File "C:\Users\Asus\projects\skillfactory\NewsPortal1\venv\lib\site-packages\django\views\generic\base.py", line 119, in dispatch
    return handler(request, *args, **kwargs)
  File "C:\Users\Asus\projects\skillfactory\NewsPortal1\venv\lib\site-packages\django\views\generic\edit.py", line 184, in post
    return super().post(request, *args, **kwargs)
  File "C:\Users\Asus\projects\skillfactory\NewsPortal1\venv\lib\site-packages\django\views\generic\edit.py", line 153, in post
    return self.form_valid(form)
  File "C:\Users\Asus\projects\skillfactory\NewsPortal1\newsWeb\news\views.py", line 108, in form_valid
    Create_news.save()
  File "C:\Users\Asus\projects\skillfactory\NewsPortal1\venv\lib\site-packages\django\db\models\base.py", line 806, in save
    self.save_base(
  File "C:\Users\Asus\projects\skillfactory\NewsPortal1\venv\lib\site-packages\django\db\models\base.py", line 872, in save_base
    post_save.send(
  File "C:\Users\Asus\projects\skillfactory\NewsPortal1\venv\lib\site-packages\django\dispatch\dispatcher.py", line 176, in send
    return [
  File "C:\Users\Asus\projects\skillfactory\NewsPortal1\venv\lib\site-packages\django\dispatch\dispatcher.py", line 177, in <listcomp>
    (receiver, receiver(signal=self, sender=sender, **named))
  File "C:\Users\Asus\projects\skillfactory\NewsPortal1\newsWeb\news\signals.py", line 27, in notify_managers_news
    logging.Logger.error ('error - can`t sent email', exc_info=1 )
TypeError: Logger.error() missing 1 required positional argument: 'msg'
07/Oct/2022 00:04:26   ERROR    C:\Users\Asus\projects\skillfactory\NewsPortal1\venv\lib\site-packages\django\core\servers\basehttp.py    "POST /home/news/create HTTP/1.1" 500 172619  None
07/Oct/2022 00:08:46   ERROR    C:\Users\Asus\projects\skillfactory\NewsPortal1\venv\lib\site-packages\django\utils\log.py    Internal Server Error: /home/news/create  (<class 'TypeError'>, TypeError("Logger.error() missing 1 required positional argument: 'msg'"), <traceback object at 0x00000243C3483400>)
Traceback (most recent call last):
  File "C:\Users\Asus\projects\skillfactory\NewsPortal1\newsWeb\news\signals.py", line 20, in notify_managers_news
    mail_managers (
  File "C:\Users\Asus\projects\skillfactory\NewsPortal1\venv\lib\site-packages\django\core\mail\__init__.py", line 154, in mail_managers
    mail.send(fail_silently=fail_silently)
  File "C:\Users\Asus\projects\skillfactory\NewsPortal1\venv\lib\site-packages\django\core\mail\message.py", line 298, in send
    return self.get_connection(fail_silently).send_messages([self])
  File "C:\Users\Asus\projects\skillfactory\NewsPortal1\venv\lib\site-packages\django\core\mail\backends\smtp.py", line 124, in send_messages
    new_conn_created = self.open()
  File "C:\Users\Asus\projects\skillfactory\NewsPortal1\venv\lib\site-packages\django\core\mail\backends\smtp.py", line 80, in open
    self.connection = self.connection_class(
  File "C:\Program Files\WindowsApps\PythonSoftwareFoundation.Python.3.10_3.10.1776.0_x64__qbz5n2kfra8p0\lib\smtplib.py", line 1050, in __init__
    SMTP.__init__(self, host, port, local_hostname, timeout,
  File "C:\Program Files\WindowsApps\PythonSoftwareFoundation.Python.3.10_3.10.1776.0_x64__qbz5n2kfra8p0\lib\smtplib.py", line 255, in __init__
    (code, msg) = self.connect(host, port)
  File "C:\Program Files\WindowsApps\PythonSoftwareFoundation.Python.3.10_3.10.1776.0_x64__qbz5n2kfra8p0\lib\smtplib.py", line 341, in connect
    self.sock = self._get_socket(host, port, self.timeout)
  File "C:\Program Files\WindowsApps\PythonSoftwareFoundation.Python.3.10_3.10.1776.0_x64__qbz5n2kfra8p0\lib\smtplib.py", line 1056, in _get_socket
    new_socket = super()._get_socket(host, port, timeout)
  File "C:\Program Files\WindowsApps\PythonSoftwareFoundation.Python.3.10_3.10.1776.0_x64__qbz5n2kfra8p0\lib\smtplib.py", line 312, in _get_socket
    return socket.create_connection((host, port), timeout,
  File "C:\Program Files\WindowsApps\PythonSoftwareFoundation.Python.3.10_3.10.1776.0_x64__qbz5n2kfra8p0\lib\socket.py", line 824, in create_connection
    for res in getaddrinfo(host, port, 0, SOCK_STREAM):
  File "C:\Program Files\WindowsApps\PythonSoftwareFoundation.Python.3.10_3.10.1776.0_x64__qbz5n2kfra8p0\lib\socket.py", line 955, in getaddrinfo
    for res in _socket.getaddrinfo(host, port, family, type, proto, flags):
socket.gaierror: [Errno 11001] getaddrinfo failed

During handling of the above exception, another exception occurred:

Traceback (most recent call last):
  File "C:\Users\Asus\projects\skillfactory\NewsPortal1\venv\lib\site-packages\django\core\handlers\exception.py", line 55, in inner
    response = get_response(request)
  File "C:\Users\Asus\projects\skillfactory\NewsPortal1\venv\lib\site-packages\django\core\handlers\base.py", line 197, in _get_response
    response = wrapped_callback(request, *callback_args, **callback_kwargs)
  File "C:\Users\Asus\projects\skillfactory\NewsPortal1\venv\lib\site-packages\django\views\generic\base.py", line 84, in view
    return self.dispatch(request, *args, **kwargs)
  File "C:\Users\Asus\projects\skillfactory\NewsPortal1\venv\lib\site-packages\django\contrib\auth\mixins.py", line 109, in dispatch
    return super().dispatch(request, *args, **kwargs)
  File "C:\Users\Asus\projects\skillfactory\NewsPortal1\venv\lib\site-packages\django\views\generic\base.py", line 119, in dispatch
    return handler(request, *args, **kwargs)
  File "C:\Users\Asus\projects\skillfactory\NewsPortal1\venv\lib\site-packages\django\views\generic\edit.py", line 184, in post
    return super().post(request, *args, **kwargs)
  File "C:\Users\Asus\projects\skillfactory\NewsPortal1\venv\lib\site-packages\django\views\generic\edit.py", line 153, in post
    return self.form_valid(form)
  File "C:\Users\Asus\projects\skillfactory\NewsPortal1\newsWeb\news\views.py", line 108, in form_valid
    Create_news.save()
  File "C:\Users\Asus\projects\skillfactory\NewsPortal1\venv\lib\site-packages\django\db\models\base.py", line 806, in save
    self.save_base(
  File "C:\Users\Asus\projects\skillfactory\NewsPortal1\venv\lib\site-packages\django\db\models\base.py", line 872, in save_base
    post_save.send(
  File "C:\Users\Asus\projects\skillfactory\NewsPortal1\venv\lib\site-packages\django\dispatch\dispatcher.py", line 176, in send
    return [
  File "C:\Users\Asus\projects\skillfactory\NewsPortal1\venv\lib\site-packages\django\dispatch\dispatcher.py", line 177, in <listcomp>
    (receiver, receiver(signal=self, sender=sender, **named))
  File "C:\Users\Asus\projects\skillfactory\NewsPortal1\newsWeb\news\signals.py", line 28, in notify_managers_news
    logging.Logger.error( "Fatal error in main loop", exc_info=True )
TypeError: Logger.error() missing 1 required positional argument: 'msg'
07/Oct/2022 00:08:46   ERROR    C:\Users\Asus\projects\skillfactory\NewsPortal1\venv\lib\site-packages\django\core\servers\basehttp.py    "POST /home/news/create HTTP/1.1" 500 172683  None
